<?xml version="1.0"?>
<robot name="wheeled_robot" xmlns:xacro="http://www.ros.org/wiki/xacro">
  <xacro:include filename="$(find mobile_robot_description)/urdf/mobile_robot2.gazebo" />
  <xacro:include filename="$(find mobile_robot_description)/urdf/materials.xacro" />

  <link name="base_footprint">
    <inertial>
      <mass value="0.0001" />
      <origin xyz="0 0 0" />
      <inertia ixx="0.0001" ixy="0.0" ixz="0.0"
          iyy="0.0001" iyz="0.0"
          izz="0.0001" />
    </inertial>
    <visual>
        <origin xyz="0 0 0" rpy="0 0 0" />
        <geometry>
            <box size="0.001 0.001 0.001" />
        </geometry>
    </visual>
  </link>

  <gazebo reference="base_footprint">
    <turnGravityOff>false</turnGravityOff>
  </gazebo>

  <joint name="base_footprint_joint" type="fixed">
    <origin xyz="0 0 -0.0197397389092321" rpy="-1.5707 0 0" />
    <parent link="base_footprint"/>
    <child link="chassis" />
  </joint>

  <link name="chassis">
    <inertial>

      <origin
        xyz="-0.147460714742137 -0.0302705388894093 0.0197397389092321"
        rpy="0 0 0" />
      <mass
        value="5.28470193836214" />
      <inertia
        ixx="0.0172196936151484"
        ixy="0.00207025336305734"
        ixz="-0.000349261147912065"
        iyy="0.0883683584210481"
        iyz="8.82258104464462E-06"
        izz="0.0760293825469887" />
    </inertial>
    <visual>
      <origin
        xyz="0 0 0"
        rpy="0 0 0" />
      <geometry>
        <mesh
          filename="package://mobile_robot_description/meshes/chassis.STL" />
      </geometry>
      <material
        name="">
        <color
          rgba="0.792156862745098 0.819607843137255 0.933333333333333 1" />
      </material>
    </visual>
    <collision>
      <origin
        xyz="0 0 0"
        rpy="0 0 0" />
      <geometry>
        <mesh
          filename="package://mobile_robot_description/meshes/chassis.STL" />
      </geometry>
    </collision>
  </link>
  <link
    name="right_wheel">
    <inertial>
      <origin
        xyz="-0.0216872360293876 4.91273688396632E-15 2.49212142519606E-07"
        rpy="0 0 0" />
      <mass
        value="0.501600220937669" />
      <inertia
        ixx="0.00143563367410199"
        ixy="-1.52145813469872E-16"
        ixz="-5.81437685180484E-10"
        iyy="0.000767786397856862"
        iyz="-1.0842021724855E-19"
        izz="0.000767786397888015" />
    </inertial>
    <visual>
      <origin
        xyz="0 0 0"
        rpy="0 0 0" />
      <geometry>
        <mesh
          filename="package://mobile_robot_description/meshes/right_wheel.STL" />
      </geometry>
      <material
        name="">
        <color
          rgba="0.792156862745098 0.819607843137255 0.933333333333333 1" />
      </material>
    </visual>
    <collision>
      <origin
        xyz="0 0 0"
        rpy="0 0 0" />
      <geometry>
        <mesh
          filename="package://mobile_robot_description/meshes/right_wheel.STL" />
      </geometry>
    </collision>
  </link>
  <joint
    name="right_wheel_joint"
    type="continuous">
    <origin
      xyz="-0.232516893895987 -0.00992377145207874 -0.0943355033260453"
      rpy="1.57079 -1.5707963267949 0" /> <!--2.06081793355236 -1.5707963267949 0-->
    <parent
      link="chassis" />
    <child
      link="right_wheel" />
    <axis
      xyz="1 0 0" />
  </joint>
  <link
    name="left_wheel">
    <inertial>
      <origin
        xyz="0.0211606147695255 2.13717932240343E-15 2.49212143400845E-07"
        rpy="0 0 0" />
      <mass
        value="0.50160022093767" />
      <inertia
        ixx="0.00143563367410199"
        ixy="6.69005152138131E-17"
        ixz="-5.81437083891871E-10"
        iyy="0.000767786397856863"
        iyz="-1.35525271560688E-20"
        izz="0.000767786397888016" />
    </inertial>
    <visual>
      <origin
        xyz="0 0 0"
        rpy="0 0 0" />
      <geometry>
        <mesh
          filename="package://mobile_robot_description/meshes/left_wheel.STL" />
      </geometry>
      <material
        name="">
        <color
          rgba="0.792156862745098 0.819607843137255 0.933333333333333 1" />
      </material>
    </visual>
    <collision>
      <origin
        xyz="0 0 0"
        rpy="0 0 0" />
      <geometry>
        <mesh
          filename="package://mobile_robot_description/meshes/left_wheel.STL" />
      </geometry>
    </collision>
  </link>
  <joint
    name="left_wheel_joint"
    type="continuous">
    <origin
      xyz="-0.232516893895987 -0.0099237714521887 0.132816645875042"
      rpy="1.5707963267949 -1.5707963267949 0" />  <!--1.36214888437792 -1.5707963267949 0-->
    <parent
      link="chassis" />
    <child
      link="left_wheel" />
    <axis
      xyz="1 0 0" />
  </joint>
  <link
    name="holder">
    <inertial>
      <origin
        xyz="-7.91033905045424E-16 0.00167070427770837 0"
        rpy="0 0 0" />
      <mass
        value="0.0145605637508094" />
      <inertia
        ixx="7.06262048877384E-06"
        ixy="1.87686475973523E-18"
        ixz="-1.05879118412685E-21"
        iyy="3.15999848872344E-06"
        iyz="1.11672116017902E-21"
        izz="9.78305610352119E-06" />
    </inertial>
    <visual>
      <origin
        xyz="0 0 0"
        rpy="0 0 0" />
      <geometry>
        <mesh
          filename="package://mobile_robot_description/meshes/holder.STL" />
      </geometry>
      <material
        name="">
        <color
          rgba="0.792156862745098 0.819607843137255 0.933333333333333 1" />
      </material>
    </visual>
    <collision>
      <origin
        xyz="0 0 0"
        rpy="0 0 0" />
      <geometry>
        <mesh
          filename="package://mobile_robot_description/meshes/holder.STL" />
      </geometry>
    </collision>
  </link>
  <joint
    name="holder_joint"
    type="fixed">
    <origin
      xyz="0.0943608907023675 0 0.0192556511477779"
      rpy="-3.14159265358973 -1.57079 0" />
    <parent
      link="chassis" />
    <child
      link="holder" />
    <axis
      xyz="0 1 0" />
  </joint>
  <link
    name="front_wheel">
    <inertial>
      <origin
        xyz="-0.0005911395494715 -6.76188943588008E-08 -7.21490811124437E-06"
        rpy="0 0 0" />
      <mass
        value="0.07939886801277" />
      <inertia
        ixx="6.61465252204961E-05"
        ixy="6.02810543812606E-12"
        ixz="-2.05702274983285E-10"
        iyy="3.52805745190462E-05"
        iyz="5.7216274092266E-11"
        izz="3.52806223740297E-05" />
    </inertial>
    <visual>
      <origin
        xyz="0 0 0"
        rpy="0 0 0" />
      <geometry>
        <mesh
          filename="package://mobile_robot_description/meshes/front_wheel.STL" />
      </geometry>
      <material
        name="">
        <color
          rgba="0.792156862745098 0.819607843137255 0.933333333333333 1" />
      </material>
    </visual>
    <collision>
      <origin
        xyz="0 0 0"
        rpy="0 0 0" />
      <geometry>
        <mesh
          filename="package://mobile_robot_description/meshes/front_wheel.STL" />
      </geometry>
    </collision>
  </link>
  <joint
    name="front_wheel_joint"
    type="continuous">
    <origin
      xyz="0 -0.0248262285478683 0"
      rpy="-1.08610219202275 -2.49800180540668E-16 7.86938930123298E-17" />
    <parent
      link="holder" />
    <child
      link="front_wheel" />
    <axis
      xyz="1 0 0" />
  </joint>





<link name="front_sensor">
  <visual>
    <geometry>
      <cylinder length="0.03" radius="0.03"/>
    </geometry>
  </visual>
</link>
<joint name="front_sensor_joint" type="fixed">
  <parent link="chassis"/>
  <child link="front_sensor"/>
  <origin xyz="0.07 -0.07 0.02" rpy="-1.5707 0 0"/>
</joint>



</robot>
